Traceback (most recent call last):
  File "E:\Program Files (x86)\Python37-32\lib\site-packages\urllib3\connectionpool.py", line 600, in urlopen
    chunked=chunked)
  File "E:\Program Files (x86)\Python37-32\lib\site-packages\urllib3\connectionpool.py", line 384, in _make_request
    six.raise_from(e, None)
  File "<string>", line 2, in raise_from
  File "E:\Program Files (x86)\Python37-32\lib\site-packages\urllib3\connectionpool.py", line 380, in _make_request
    httplib_response = conn.getresponse()
  File "E:\Program Files (x86)\Python37-32\lib\http\client.py", line 1321, in getresponse
    response.begin()
  File "E:\Program Files (x86)\Python37-32\lib\http\client.py", line 296, in begin
    version, status, reason = self._read_status()
  File "E:\Program Files (x86)\Python37-32\lib\http\client.py", line 265, in _read_status
    raise RemoteDisconnected("Remote end closed connection without"
http.client.RemoteDisconnected: Remote end closed connection without response

During handling of the above exception, another exception occurred:

Traceback (most recent call last):
  File "E:\Program Files (x86)\Python37-32\lib\site-packages\requests\adapters.py", line 445, in send
    timeout=timeout
  File "E:\Program Files (x86)\Python37-32\lib\site-packages\urllib3\connectionpool.py", line 638, in urlopen
    _stacktrace=sys.exc_info()[2])
  File "E:\Program Files (x86)\Python37-32\lib\site-packages\urllib3\util\retry.py", line 398, in increment
    raise MaxRetryError(_pool, url, error or ResponseError(cause))
urllib3.exceptions.MaxRetryError: HTTPSConnectionPool(host='wx2.qq.com', port=443): Max retries exceeded with url: /cgi-bin/mmwebwx-bin/webwxsync?sid=wUdV3udVlg8A6Kqr&skey=@crypt_f675a980_80ed42bd0d7d74a624784603ca6b9452&pass_ticket=jo%2F7zpdYh5TpBqqpIwI9amTxlgjMCKe6xQE%2BXSaO4eY%3D (Caused by ProxyError('Cannot connect to proxy.', RemoteDisconnected('Remote end closed connection without response')))

During handling of the above exception, another exception occurred:

Traceback (most recent call last):
  File "E:\Program Files (x86)\Python37-32\lib\site-packages\itchat\components\login.py", line 253, in maintain_loop
    msgList, contactList = self.get_msg()
  File "E:\Program Files (x86)\Python37-32\lib\site-packages\itchat\components\login.py", line 334, in get_msg
    r = self.s.post(url, data=json.dumps(data), headers=headers, timeout=config.TIMEOUT)
  File "E:\Program Files (x86)\Python37-32\lib\site-packages\requests\sessions.py", line 559, in post
    return self.request('POST', url, data=data, json=json, **kwargs)
  File "E:\Program Files (x86)\Python37-32\lib\site-packages\requests\sessions.py", line 512, in request
    resp = self.send(prep, **send_kwargs)
  File "E:\Program Files (x86)\Python37-32\lib\site-packages\requests\sessions.py", line 622, in send
    r = adapter.send(request, **kwargs)
  File "E:\Program Files (x86)\Python37-32\lib\site-packages\requests\adapters.py", line 507, in send
    raise ProxyError(e, request=request)
requests.exceptions.ProxyError: HTTPSConnectionPool(host='wx2.qq.com', port=443): Max retries exceeded with url: /cgi-bin/mmwebwx-bin/webwxsync?sid=wUdV3udVlg8A6Kqr&skey=@crypt_f675a980_80ed42bd0d7d74a624784603ca6b9452&pass_ticket=jo%2F7zpdYh5TpBqqpIwI9amTxlgjMCKe6xQE%2BXSaO4eY%3D (Caused by ProxyError('Cannot connect to proxy.', RemoteDisconnected('Remote end closed connection without response')))